<h1>try...catchを使ったエラーハンドリングの練習用問題</h1>
<h2>問題5: 再試行ロジックの実装</h2>
<h3>要件</h3>
<ol>
    <li>最大3回までリトライ可能なAPI呼び出し関数を作成</li>
    <li>エラー発生時に1秒間隔で再試行</li>
    <li>3回失敗したら最終エラーを投げる</li>
    <li>ヒント: forループとawaitの組み合わせ</li>
</ol>
<p id="message"></p>

<script>
    async function unstableAPI() {
        return new Promise((resolve, reject) => {
            const success = Math.random() > 0.5;
            setTimeout(() => {
                success ? resolve('成功') : reject('一時的なエラー');
            }, 300);
        });
    }
    // ここに解答コードを書いてください
    async function callWithRetry() {
        const messageElement = document.getElementById('message');
        const maxAttempts = 3; // 最大試行回数（初回含む）
        let lastError;

        for (let attempt = 1; attempt <= maxAttempts; attempt++) {
            try {
                const result = await unstableAPI();
                messageElement.textContent = `${attempt}回目で取得成功`;
                messageElement.style.color = 'green';
                return result; // 成功時は結果を返す
            } catch (error) {
                lastError = error;
                messageElement.textContent = `${attempt}/${maxAttempts}回目 失敗`;
                messageElement.style.color = 'orange';

                if (attempt < maxAttempts) {
                    console.error(`リトライ待機中... (${maxAttempts - attempt}回残り)`);
                    await new Promise(resolve => setTimeout(resolve, 1000));
                }
            }
        }

        messageElement.textContent = `${maxAttempts}回試行しましたが失敗`;
        messageElement.style.color = 'red';
        throw new Error(`最終エラー: ${lastError.message}`); // エラーを再スロー
    }

    // 実行例
    callWithRetry()
        .catch(error => {
            console.error('全体失敗:', error);
        });

</script>