<h1>try...catchを使ったエラーハンドリングの練習用問題</h1>
<h2>問題2: ネストしたAPIリクエスト</h2>
<h3>要件</h3>
<ol>
    <li>fetchUser(userId)でユーザーデータ取得</li>
    <li>取得したユーザーのpostIdを使用してfetchPost(postId)で投稿データ取得</li>
    <li>各段階でエラーハンドリングを実施</li>
    <li>エラー発生時は「データ取得に失敗しました」と表示</li>
</ol>
<p id="post"></p>

<script>
// 模擬API関数
async function fetchUser(userId) {
  return new Promise((resolve, reject) => {
    setTimeout(() => {
      if (userId === 1) {
        resolve({ id: 1, postId: 101 });
      } else {
        reject('ユーザーが見つかりません');
      }
    }, 500);
  });
}

async function fetchPost(postId) {
  return new Promise((resolve, reject) => {
    setTimeout(() => {
      if (postId === 102) {
        resolve({ id: 101, title: 'JavaScript Tips' });
        //resolve({ id: 101 });
      } else {
        reject('投稿が見つかりません');
      }
    }, 500);
  });
}

// ここに解答コードを書いてください
async function getUserPost(userID) {
  // API呼び出しとエラーハンドリング
  const postElement = document.getElementById('post');

  try {
    const user = await fetchUser(userID);
    const post = await fetchPost(user.postId);

    if(!post.title) {
        throw new Error('タイトルが存在しません');
    }
    postElement.textContent = post.title;
  } catch(error) {
    postElement.textContent = error.message;
    console.error(error);
  }
}

getUserPost(1);
//getUserPost(99);

</script>